Watching for file changes with StatReloader
Exception in thread django-main-thread:
Traceback (most recent call last):
  File "/usr/local/lib/python3.13/threading.py", line 1041, in _bootstrap_inner
    self.run()
    ~~~~~~~~^^
  File "/usr/local/lib/python3.13/threading.py", line 992, in run
    self._target(*self._args, **self._kwargs)
    ~~~~~~~~~~~~^^^^^^^^^^^^^^^^^^^^^^^^^^^^^
  File "/root/InviLink/DjangoApp/venv/lib/python3.13/site-packages/django/utils/autoreload.py", line 64, in wrapper
    fn(*args, **kwargs)
    ~~^^^^^^^^^^^^^^^^^
  File "/root/InviLink/DjangoApp/venv/lib/python3.13/site-packages/django/core/management/commands/runserver.py", line 134, in inner_run
    self.check(display_num_errors=True)
    ~~~~~~~~~~^^^^^^^^^^^^^^^^^^^^^^^^^
  File "/root/InviLink/DjangoApp/venv/lib/python3.13/site-packages/django/core/management/base.py", line 486, in check
    all_issues = checks.run_checks(
        app_configs=app_configs,
    ...<2 lines>...
        databases=databases,
    )
  File "/root/InviLink/DjangoApp/venv/lib/python3.13/site-packages/django/core/checks/registry.py", line 88, in run_checks
    new_errors = check(app_configs=app_configs, databases=databases)
  File "/root/InviLink/DjangoApp/venv/lib/python3.13/site-packages/django/core/checks/urls.py", line 16, in check_url_config
    return check_resolver(resolver)
  File "/root/InviLink/DjangoApp/venv/lib/python3.13/site-packages/django/core/checks/urls.py", line 26, in check_resolver
    return check_method()
  File "/root/InviLink/DjangoApp/venv/lib/python3.13/site-packages/django/urls/resolvers.py", line 531, in check
    for pattern in self.url_patterns:
                   ^^^^^^^^^^^^^^^^^
  File "/root/InviLink/DjangoApp/venv/lib/python3.13/site-packages/django/utils/functional.py", line 47, in __get__
    res = instance.__dict__[self.name] = self.func(instance)
                                         ~~~~~~~~~^^^^^^^^^^
  File "/root/InviLink/DjangoApp/venv/lib/python3.13/site-packages/django/urls/resolvers.py", line 718, in url_patterns
    patterns = getattr(self.urlconf_module, "urlpatterns", self.urlconf_module)
                       ^^^^^^^^^^^^^^^^^^^
  File "/root/InviLink/DjangoApp/venv/lib/python3.13/site-packages/django/utils/functional.py", line 47, in __get__
    res = instance.__dict__[self.name] = self.func(instance)
                                         ~~~~~~~~~^^^^^^^^^^
  File "/root/InviLink/DjangoApp/venv/lib/python3.13/site-packages/django/urls/resolvers.py", line 711, in urlconf_module
    return import_module(self.urlconf_name)
  File "/usr/local/lib/python3.13/importlib/__init__.py", line 88, in import_module
    return _bootstrap._gcd_import(name[level:], package, level)
           ~~~~~~~~~~~~~~~~~~~~~~^^^^^^^^^^^^^^^^^^^^^^^^^^^^^^
  File "<frozen importlib._bootstrap>", line 1387, in _gcd_import
  File "<frozen importlib._bootstrap>", line 1360, in _find_and_load
  File "<frozen importlib._bootstrap>", line 1331, in _find_and_load_unlocked
  File "<frozen importlib._bootstrap>", line 935, in _load_unlocked
  File "<frozen importlib._bootstrap_external>", line 1022, in exec_module
  File "<frozen importlib._bootstrap>", line 488, in _call_with_frames_removed
  File "/root/InviLink/DjangoApp/InviLinkApp/urls.py", line 18, in <module>
    path('', include('auth_blockchain.urls')),
             ~~~~~~~^^^^^^^^^^^^^^^^^^^^^^^^
  File "/root/InviLink/DjangoApp/venv/lib/python3.13/site-packages/django/urls/conf.py", line 39, in include
    urlconf_module = import_module(urlconf_module)
  File "/usr/local/lib/python3.13/importlib/__init__.py", line 88, in import_module
    return _bootstrap._gcd_import(name[level:], package, level)
           ~~~~~~~~~~~~~~~~~~~~~~^^^^^^^^^^^^^^^^^^^^^^^^^^^^^^
  File "<frozen importlib._bootstrap>", line 1387, in _gcd_import
  File "<frozen importlib._bootstrap>", line 1360, in _find_and_load
  File "<frozen importlib._bootstrap>", line 1331, in _find_and_load_unlocked
  File "<frozen importlib._bootstrap>", line 935, in _load_unlocked
  File "<frozen importlib._bootstrap_external>", line 1022, in exec_module
  File "<frozen importlib._bootstrap>", line 488, in _call_with_frames_removed
  File "/root/InviLink/DjangoApp/auth_blockchain/urls.py", line 2, in <module>
    from . import views
  File "/root/InviLink/DjangoApp/auth_blockchain/views.py", line 1, in <module>
    from nacl.public import PrivateKey, PublicKey, Box
ModuleNotFoundError: No module named 'nacl'
Watching for file changes with StatReloader
Error: That port is already in use.
